---
description: 'Дополнительные сведения: оператор "Throw" не может опускать операнд вне оператора "Catch" или внутри оператора "finally"'
title: В операторе Throw запрещается опускать операнд вне оператора Catch и в операторе Finally
ms.date: 07/20/2015
f1_keywords:
- vbc30666
- bc30666
helpviewer_keywords:
- BC30666
ms.assetid: a208a6ea-0e36-4bf1-8984-4de1a0e38a2a
ms.openlocfilehash: 8ab76ae9e5727388ddb77ec38f1b4e89b6a0e5d6
ms.sourcegitcommit: 10e719780594efc781b15295e499c66f316068b8
ms.translationtype: MT
ms.contentlocale: ru-RU
ms.lasthandoff: 02/14/2021
ms.locfileid: "100460843"
---
# <a name="throw-statement-cannot-omit-operand-outside-a-catch-statement-or-inside-a-finally-statement"></a>В операторе Throw запрещается опускать операнд вне оператора Catch и в операторе Finally

В операторах`Throw` , находящихся вне оператора `Catch` , должно быть указано имя объекта исключения.  
  
 **Идентификатор ошибки:** BC30666  
  
## <a name="to-correct-this-error"></a>Исправление ошибки  
  
1. Укажите имя объекта исключения, производного от класса `System.Exception`.  
  
2. Измените структуру кода таким образом, чтобы оператор `Throw` находился внутри блока `Catch` .  
  
## <a name="see-also"></a>См. также раздел

- [Оператор Throw](../language-reference/statements/throw-statement.md)
- [Оператор Try...Catch...Finally](../language-reference/statements/try-catch-finally-statement.md)
- <xref:System.Exception?displayProperty=nameWithType>
- [Обработка и создание исключений в .NET](../../standard/exceptions/index.md)
